<?xml version="1.0" ?>
<robot name="manipulator">

  <!-- <link name="world"></link> -->

  <!-- Link 1 -->
  <link name="link1">
    <inertial>
      <mass value="1.0" />
      <origin xyz="0 0 0.5" />
      <inertia ixx="0.1" ixy="0" ixz="0" iyy="0.1" iyz="0" izz="0.1" />
    </inertial>
    <visual>
      <origin xyz="0 0 0.5" />
      <geometry>
        <box size="0.1 0.1 1.0" />
      </geometry>
      <material name="blue">
        <color rgba="0.0 0.0 1.0 1.0" />
      </material>
    </visual>
    <collision>
      <origin xyz="0 0 0.5" />
      <geometry>
        <box size="0.1 0.1 1.0" />
      </geometry>
    </collision>
  </link>

  <!-- Link 2 -->
  <link name="link2">
    <inertial>
      <mass value="1.0" />
      <origin xyz="0 0 0.5" />
      <inertia ixx="0.1" ixy="0" ixz="0" iyy="0.1" iyz="0" izz="0.1" />
    </inertial>
    <visual>
      <origin xyz="0 0 0.5" />
      <geometry>
        <box size="0.1 0.1 1.0" />
      </geometry>
      <material name="green">
        <color rgba="0.0 1.0 0.0 1.0" />
      </material>
    </visual>
    <collision>
      <origin xyz="0 0 0.5" />
      <geometry>
        <box size="0.1 0.1 1.0" />
      </geometry>
    </collision>
  </link>

  <!-- Link 3 -->
  <link name="link3">
    <inertial>
      <mass value="1.0" />
      <origin xyz="0 0 0.5" />
      <inertia ixx="0.1" ixy="0" ixz="0" iyy="0.1" iyz="0" izz="0.1" />
    </inertial>
    <visual>
      <origin xyz="0 0 0.5" />
      <geometry>
        <box size="0.1 0.1 1.0" />
      </geometry>
      <material name="red">
        <color rgba="1.0 0.0 0.0 1.0" />
      </material>
    </visual>
    <collision>
      <origin xyz="0 0 0.5" />
      <geometry>
        <box size="0.1 0.1 1.0" />
      </geometry>
    </collision>
  </link>

  <!-- Link 4 -->
  <link name="link4">
    <inertial>
      <mass value="1.0" />
      <origin xyz="0 0 0.5" />
      <inertia ixx="0.1" ixy="0" ixz="0" iyy="0.1" iyz="0" izz="0.1" />
    </inertial>
    <visual>
      <origin xyz="0 0 0.5" />
      <geometry>
        <box size="0.1 0.1 1.0" />
      </geometry>
      <material name="yellow">
        <color rgba="1.0 1.0 0.0 1.0" />
      </material>
    </visual>
    <collision>
      <origin xyz="0 0 0.5" />
      <geometry>
        <box size="0.1 0.1 1.0" />
      </geometry>
    </collision>
  </link>

  <!-- Link 5 -->
  <link name="link5">
    <inertial>
      <mass value="1.0" />
      <origin xyz="0 0 0.5" />
      <inertia ixx="0.1" ixy="0" ixz="0" iyy="0.1" iyz="0" izz="0.1" />
    </inertial>
    <visual>
      <origin xyz="0 0 0.5" />
      <geometry>
        <box size="0.1 0.1 1.0" />
      </geometry>
      <material name="cyan">
        <color rgba="0.0 1.0 1.0 1.0" />
      </material>
    </visual>
    <collision>
      <origin xyz="0 0 0.5" />
      <geometry>
        <box size="0.1 0.1 1.0" />
      </geometry>
    </collision>
  </link>

  <!-- Link 6 -->
  <link name="link6">
    <inertial>
      <mass value="1.0" />
      <origin xyz="0 0 0.5" />
      <inertia ixx="0.1" ixy="0" ixz="0" iyy="0.1" iyz="0" izz="0.1" />
    </inertial>
    <visual>
      <origin xyz="0 0 0.5" />
      <geometry>
        <box size="0.1 0.1 1.0" />
      </geometry>
      <material name="magenta">
        <color rgba="1.0 0.0 1.0 1.0" />
      </material>
    </visual>
    <collision>
      <origin xyz="0 0 0.5" />
      <geometry>
        <box size="0.1 0.1 1.0" />
      </geometry>
    </collision>
  </link>



  <!-- Joint 2 -->
  <joint name="joint2" type="revolute">
    <parent link="link1" />
    <child link="link2" />
    <origin xyz="0 0 1.0" rpy="0 0 0" />
    <axis xyz="0 1 0" />
    <limit effort="100.0" lower="-3.14" upper="3.14" velocity="1.0" />
    <dynamics damping="0.1" friction="0.0" />
  </joint>

  <!-- Joint 3 -->
  <joint name="joint3" type="revolute">
    <parent link="link2" />
    <child link="link3" />
    <origin xyz="0 0 1.0" rpy="0 0 0" />
    <axis xyz="0 1 0" />
    <limit effort="100.0" lower="-3.14" upper="3.14" velocity="1.0" />
    <dynamics damping="0.1" friction="0.0" />
  </joint>

  <!-- Joint 4 -->
  <joint name="joint4" type="revolute">
    <parent link="link3" />
    <child link="link4" />
    <origin xyz="0 0 1.0" rpy="0 0 0" />
    <axis xyz="0 1 0" />
    <limit effort="100.0" lower="-3.14" upper="3.14" velocity="1.0" />
    <dynamics damping="0.1" friction="0.0" />
  </joint>

  <!-- Joint 5 -->
  <joint name="joint5" type="revolute">
    <parent link="link4" />
    <child link="link5" />
    <origin xyz="0 0 1.0" rpy="0 0 0" />
    <axis xyz="0 1 0" />
    <limit effort="100.0" lower="-3.14" upper="3.14" velocity="1.0" />
    <dynamics damping="0.1" friction="0.0" />
  </joint>

  <!-- Joint 6 -->
  <joint name="joint6" type="revolute">
    <parent link="link5" />
    <child link="link6" />
    <origin xyz="0 0 1.0" rpy="0 0 0" />
    <axis xyz="0 1 0" />
    <limit effort="100.0" lower="-3.14" upper="3.14" velocity="1.0" />
    <dynamics damping="0.1" friction="0.0" />
  </joint>

</robot>
