<?xml version="1.0"?>
<robot name="biped">

    <!-- Define the body parameters -->
    <link name="base_link">
        <visual>
            <origin xyz="0 0 0" rpy="0 0 0"/>
            <geometry>
                <box size="0.2 0.5 0.6" />
            </geometry>
            <material name="green">
                <color rgba="0.2 1 0.2 1"/>
            </material>
        </visual>
        <collision>
            <origin xyz="0 0 0" rpy="0 0 0"/>
            <geometry>
                <box size="0.2 0.5 0.6" />
            </geometry>
        </collision>
        <inertial>
            <origin xyz="0 0 0" rpy="0 0 0"/>
            <mass value="0.001" />
            <inertia ixx="2.26" ixy="0.0" ixz="0.0" iyy="6.26" iyz="0.0" izz="8.5" />
        </inertial>
    </link>

    <joint name="toss_joint_1" type="revolute"> 
        <origin xyz="0 0 -0.3" rpy="0 0 0"/>
        <parent link="base_link"/>
        <child link="thigh_link_1"/>
        <axis xyz="0 -1 0"/>
        <limit lower="-1.047" upper="1.571" velocity="100" effort="100"/> 
    </joint>

    <link name="thigh_link_1">
        <visual>
            <origin xyz="0 0 -0.25" rpy="0 0 0"/>
            <geometry>                
                <cylinder length="0.5" radius="0.05" />
            </geometry>
            <material name="orange">
                <color rgba="1 0.3 0.1 1"/>
            </material>
        </visual>
        <collision>
            <origin xyz="0 0 -0.25" rpy="0 0 0"/>
            <geometry>
                <cylinder length="0.5" radius="0.05" />
            </geometry>
        </collision>
        <inertial>
            <origin xyz="0 0 -0.25" rpy="0 0 0"/>
            <mass value="10.0" />
            <inertia ixx="0.021875" ixy="0.0" ixz="0.0" iyy="0.021875" iyz="0.0" izz="0.0125" />
        </inertial>
    </link>

    <joint name="toss_joint_2" type="revolute"> 
        <origin xyz="0 0 -0.3" rpy="0 0 0"/>
        <parent link="base_link"/>
        <child link="thigh_link_2"/>
        <axis xyz="0 -1 0"/>
        <limit lower="-1.047" upper="1.571" velocity="100" effort="100"/> 
    </joint>

    <link name="thigh_link_2">
        <visual>
            <origin xyz="0 0 -0.25" rpy="0 0 0"/>
            <geometry>                
                <cylinder length="0.5" radius="0.05" />
            </geometry>
            <material name="blue">
                <color rgba="1 0.3 0.1 1"/>
            </material>
        </visual>
        <collision>
            <origin xyz="0 0 -0.25" rpy="0 0 0"/>
            <geometry>
                <cylinder length="0.5" radius="0.05" />
            </geometry>
        </collision>
        <inertial>
            <origin xyz="0 0 -0.25" rpy="0 0 0"/>
            <mass value="10.0" />
            <inertia ixx="0.021875" ixy="0.0" ixz="0.0" iyy="0.021875" iyz="0.0" izz="0.0125" />
        </inertial>
    </link>

    <joint name="knee_joint_1" type="revolute"> 
        <origin xyz="0 0 -0.5" rpy="0 0 0"/>
        <parent link="thigh_link_1"/>
        <child link="calf_link_1"/>
        <axis xyz="0 -1 0"/>
        <limit lower="-1.571" upper="0" velocity="100" effort="100"/> 
    </joint>

    <link name="calf_link_1">
        <visual>
            <origin xyz="0 0 -0.25" rpy="0 0 0"/>
            <geometry>                
                <cylinder length="0.5" radius="0.05" />
            </geometry>
            <material name="orange">
                <color rgba="1 0.3 0.1 1"/>
            </material>
        </visual>
        <collision>
            <origin xyz="0 0 -0.25" rpy="0 0 0"/>
            <geometry>
                <cylinder length="0.5" radius="0.05" />
            </geometry>
        </collision>
        <inertial>
            <origin xyz="0 0 -0.25" rpy="0 0 0"/>
            <mass value="10.0" />
            <inertia ixx="0.021875" ixy="0.0" ixz="0.0" iyy="0.021875" iyz="0.0" izz="0.0125" />
        </inertial>
    </link>

    <joint name="knee_joint_2" type="revolute"> 
        <origin xyz="0 0 -0.5" rpy="0 0 0"/>
        <parent link="thigh_link_2"/>
        <child link="calf_link_2"/>
        <axis xyz="0 -1 0"/>
        <limit lower="-1.571" upper="0" velocity="100" effort="100"/> 
    </joint>

    <link name="calf_link_2">
        <visual>
            <origin xyz="0 0 -0.25" rpy="0 0 0"/>
            <geometry>                
                <cylinder length="0.5" radius="0.05" />
            </geometry>
            <material name="blue">
                <color rgba="1 0.3 0.1 1"/>
            </material>
        </visual>
        <collision>
            <origin xyz="0 0 -0.25" rpy="0 0 0"/>
            <geometry>
                <cylinder length="0.5" radius="0.05" />
            </geometry>
        </collision>
        <inertial>
            <origin xyz="0 0 -0.25" rpy="0 0 0"/>
            <mass value="10.0" />
            <inertia ixx="0.021875" ixy="0.0" ixz="0.0" iyy="0.021875" iyz="0.0" izz="0.0125" />
        </inertial>
    </link>

    <joint name="ankle_joint_1" type="fixed"> 
        <origin xyz="0 0 -0.5" rpy="0 0 0"/>
        <parent link="calf_link_1"/>
        <child link="foot_link_1"/>
    </joint>

    <link name="foot_link_1">
        <visual>
            <origin xyz="0.1 0 0" rpy="0 0 0"/>
            <geometry>
                <box size="0.2 0.1 0.05" />
            </geometry>
            <material name="green">
                <color rgba="0.2 1 0.2 1"/>
            </material>
        </visual>
        <collision>
            <origin xyz="0.1 0 0" rpy="0 0 0"/>
            <geometry>
                <box size="0.2 0.1 0.05" />
            </geometry>
        </collision>
        <inertial>
            <origin xyz="0.1 0 0" rpy="0 0 0"/>
            <mass value="2" />
            <inertia ixx="2.26" ixy="0.0" ixz="0.0" iyy="6.26" iyz="0.0" izz="8.5" />
        </inertial>
    </link>

    <joint name="ankle_joint_2" type="fixed"> 
        <origin xyz="0 0 -0.5" rpy="0 0 0"/>
        <parent link="calf_link_2"/>
        <child link="foot_link_2"/>
    </joint>

    <link name="foot_link_2">
        <visual>
            <origin xyz="0.1 0 0" rpy="0 0 0"/>
            <geometry>
                <box size="0.2 0.1 0.05" />
            </geometry>
            <material name="green">
                <color rgba="0.2 1 0.2 1"/>
            </material>
        </visual>
        <collision>
            <origin xyz="0.1 0 0" rpy="0 0 0"/>
            <geometry>
                <box size="0.2 0.1 0.05" />
            </geometry>
        </collision>
        <inertial>
            <origin xyz="0.1 0 0" rpy="0 0 0"/>
            <mass value="2" />
            <inertia ixx="2.26" ixy="0.0" ixz="0.0" iyy="6.26" iyz="0.0" izz="8.5" />
        </inertial>
    </link>


</robot>
